 * Serving Flask app 'proxy_server'
 * Debug mode: off
WARNING: This is a development server. Do not use it in a production deployment. Use a production WSGI server instead.
 * Running on http://127.0.0.1:8000
Press CTRL+C to quit
Traceback (most recent call last):
  File "/usr/lib/python3/dist-packages/urllib3/connection.py", line 169, in _new_conn
    conn = connection.create_connection(
  File "/usr/lib/python3/dist-packages/urllib3/util/connection.py", line 96, in create_connection
    raise err
  File "/usr/lib/python3/dist-packages/urllib3/util/connection.py", line 86, in create_connection
    sock.connect(sa)
ConnectionRefusedError: [Errno 111] Connection refused

During handling of the above exception, another exception occurred:

Traceback (most recent call last):
  File "/usr/lib/python3/dist-packages/urllib3/connectionpool.py", line 699, in urlopen
    httplib_response = self._make_request(
  File "/usr/lib/python3/dist-packages/urllib3/connectionpool.py", line 394, in _make_request
    conn.request(method, url, **httplib_request_kw)
  File "/usr/lib/python3/dist-packages/urllib3/connection.py", line 234, in request
    super(HTTPConnection, self).request(method, url, body=body, headers=headers)
  File "/usr/lib/python3.10/http/client.py", line 1283, in request
    self._send_request(method, url, body, headers, encode_chunked)
  File "/usr/lib/python3.10/http/client.py", line 1329, in _send_request
    self.endheaders(body, encode_chunked=encode_chunked)
  File "/usr/lib/python3.10/http/client.py", line 1278, in endheaders
    self._send_output(message_body, encode_chunked=encode_chunked)
  File "/usr/lib/python3.10/http/client.py", line 1038, in _send_output
    self.send(msg)
  File "/usr/lib/python3.10/http/client.py", line 976, in send
    self.connect()
  File "/usr/lib/python3/dist-packages/urllib3/connection.py", line 200, in connect
    conn = self._new_conn()
  File "/usr/lib/python3/dist-packages/urllib3/connection.py", line 181, in _new_conn
    raise NewConnectionError(
urllib3.exceptions.NewConnectionError: <urllib3.connection.HTTPConnection object at 0x7f4a927cfee0>: Failed to establish a new connection: [Errno 111] Connection refused

During handling of the above exception, another exception occurred:

Traceback (most recent call last):
  File "/usr/lib/python3/dist-packages/requests/adapters.py", line 439, in send
    resp = conn.urlopen(
  File "/usr/lib/python3/dist-packages/urllib3/connectionpool.py", line 755, in urlopen
    retries = retries.increment(
  File "/usr/lib/python3/dist-packages/urllib3/util/retry.py", line 574, in increment
    raise MaxRetryError(_pool, url, error or ResponseError(cause))
urllib3.exceptions.MaxRetryError: HTTPConnectionPool(host='127.0.0.1', port=8000): Max retries exceeded with url: //gettoken (Caused by NewConnectionError('<urllib3.connection.HTTPConnection object at 0x7f4a927cfee0>: Failed to establish a new connection: [Errno 111] Connection refused'))

During handling of the above exception, another exception occurred:

Traceback (most recent call last):
  File "/home/zero/hack/RoadTripPlanner/backend/server.py", line 90, in <module>
    get_route_points_and_avg_speed(TRIP['start'], TRIP['dest'])
  File "/home/zero/hack/RoadTripPlanner/backend/server.py", line 74, in get_route_points_and_avg_speed
    refresh_tok()
  File "/home/zero/hack/RoadTripPlanner/backend/server.py", line 66, in refresh_tok
    response = requests.get(PROXY_SERVER+"/gettoken")
  File "/usr/lib/python3/dist-packages/requests/api.py", line 76, in get
    return request('get', url, params=params, **kwargs)
  File "/usr/lib/python3/dist-packages/requests/api.py", line 61, in request
    return session.request(method=method, url=url, **kwargs)
  File "/usr/lib/python3/dist-packages/requests/sessions.py", line 544, in request
    resp = self.send(prep, **send_kwargs)
  File "/usr/lib/python3/dist-packages/requests/sessions.py", line 657, in send
    r = adapter.send(request, **kwargs)
  File "/usr/lib/python3/dist-packages/requests/adapters.py", line 516, in send
    raise ConnectionError(e, request=request)
requests.exceptions.ConnectionError: HTTPConnectionPool(host='127.0.0.1', port=8000): Max retries exceeded with url: //gettoken (Caused by NewConnectionError('<urllib3.connection.HTTPConnection object at 0x7f4a927cfee0>: Failed to establish a new connection: [Errno 111] Connection refused'))
 * Serving Flask app 'proxy_server'
 * Debug mode: off
WARNING: This is a development server. Do not use it in a production deployment. Use a production WSGI server instead.
 * Running on http://127.0.0.1:8000
Press CTRL+C to quit
127.0.0.1 - - [11/Nov/2023 19:59:28] "GET /gettoken HTTP/1.1" 200 -
127.0.0.1 - - [11/Nov/2023 19:59:29] "GET /getroute HTTP/1.1" 200 -
[[-122.44254506472082, 37.77055890498698], [-122.44294881820679, 37.77050256729126], [-122.44303464889526, 37.77048110961914], [-122.44335651397705, 37.77045965194702], [-122.44367837905884, 37.77041673660278], [-122.44346380233765, 37.76947259902954], [-122.44344234466553, 37.769408226013184], [-122.44333505630493, 37.76893615722656], [-122.44361400604248, 37.76829242706299], [-122.44372129440308, 37.7679705619812], [-122.44387149810791, 37.7675199508667], [-122.44376420974731, 37.767090797424316], [-122.44369983673096, 37.76694059371948], [-122.44339942932129, 37.76657581329346], [-122.44335651397705, 37.76655435562134], [-122.44320631027222, 37.76646852493286], [-122.44312047958374, 37.766382694244385], [-122.44305610656738, 37.76625394821167], [-122.44301319122314, 37.766146659851074], [-122.44292736053467, 37.76608228683472], [-122.44277715682983, 37.76597499847412], [-122.44266986846924, 37.765910625457764], [-122.44282007217407, 37.76578187942505], [-122.44339942932129, 37.765395641326904], [-122.44348526000977, 37.765352725982666], [-122.4427342414856, 37.76530981063843], [-122.44258403778076, 37.76530981063843], [-122.44252658518187, 37.76529832011865]]
11
 * Serving Flask app 'server'
 * Debug mode: on
WARNING: This is a development server. Do not use it in a production deployment. Use a production WSGI server instead.
 * Running on all addresses (0.0.0.0)
 * Running on http://127.0.0.1:5000
 * Running on http://192.168.210.38:5000
Press CTRL+C to quit
 * Restarting with stat
127.0.0.1 - - [11/Nov/2023 19:59:30] "GET /gettoken HTTP/1.1" 200 -
127.0.0.1 - - [11/Nov/2023 19:59:31] "GET /getroute HTTP/1.1" 200 -
 * Debugger is active!
 * Debugger PIN: 707-806-998
 * Detected change in '/home/zero/hack/RoadTripPlanner/backend/server.py', reloading
[[-122.44254506472082, 37.77055890498698], [-122.44294881820679, 37.77050256729126], [-122.44303464889526, 37.77048110961914], [-122.44335651397705, 37.77045965194702], [-122.44367837905884, 37.77041673660278], [-122.44346380233765, 37.76947259902954], [-122.44344234466553, 37.769408226013184], [-122.44333505630493, 37.76893615722656], [-122.44361400604248, 37.76829242706299], [-122.44372129440308, 37.7679705619812], [-122.44387149810791, 37.7675199508667], [-122.44376420974731, 37.767090797424316], [-122.44369983673096, 37.76694059371948], [-122.44339942932129, 37.76657581329346], [-122.44335651397705, 37.76655435562134], [-122.44320631027222, 37.76646852493286], [-122.44312047958374, 37.766382694244385], [-122.44305610656738, 37.76625394821167], [-122.44301319122314, 37.766146659851074], [-122.44292736053467, 37.76608228683472], [-122.44277715682983, 37.76597499847412], [-122.44266986846924, 37.765910625457764], [-122.44282007217407, 37.76578187942505], [-122.44339942932129, 37.765395641326904], [-122.44348526000977, 37.765352725982666], [-122.4427342414856, 37.76530981063843], [-122.44258403778076, 37.76530981063843], [-122.44252658518187, 37.76529832011865]]
11
